//
// Copyright (C) 2012-2024 Stealth Software Technologies, Inc.
//
// Permission is hereby granted, free of charge, to any person
// obtaining a copy of this software and associated documentation
// files (the "Software"), to deal in the Software without
// restriction, including without limitation the rights to use,
// copy, modify, merge, publish, distribute, sublicense, and/or
// sell copies of the Software, and to permit persons to whom the
// Software is furnished to do so, subject to the following
// conditions:
//
// The above copyright notice and this permission notice (including
// the next paragraph) shall be included in all copies or
// substantial portions of the Software.
//
// THE SOFTWARE IS PROVIDED "AS IS", WITHOUT WARRANTY OF ANY KIND,
// EXPRESS OR IMPLIED, INCLUDING BUT NOT LIMITED TO THE WARRANTIES
// OF MERCHANTABILITY, FITNESS FOR A PARTICULAR PURPOSE AND
// NONINFRINGEMENT. IN NO EVENT SHALL THE AUTHORS OR COPYRIGHT
// HOLDERS BE LIABLE FOR ANY CLAIM, DAMAGES OR OTHER LIABILITY,
// WHETHER IN AN ACTION OF CONTRACT, TORT OR OTHERWISE, ARISING
// FROM, OUT OF OR IN CONNECTION WITH THE SOFTWARE OR THE USE OR
// OTHER DEALINGS IN THE SOFTWARE.
//
// SPDX-License-Identifier: MIT
//

#include <TEST_EXIT.h>
#include <climits>
#include <exception>
#include <iostream>
#include <sst/catalog/perfect_ne.hpp>
#include <string>

namespace {

struct fail {};

void test(bool const x, std::string const & x_str) {
  if (x) {
    std::cout << "pass: " << x_str << std::endl;
  } else {
    std::cout << "fail: " << x_str << std::endl;
    throw fail();
  }
}

#define TEST2(x) test(x, #x)

#define TEST(a, b) \
  do { \
    TEST2((sst::perfect_ne(a, b))); \
    TEST2((sst::perfect_ne(b, a))); \
  } while (false)

} // namespace

int main() {
  try {

    TEST(false, true);
    TEST(false, 1);
    TEST(false, 1U);

    TEST(0, 1);
    TEST(0, 1U);
    TEST(0U, 1);
    TEST(0U, 1U);

    TEST(-1, 0);
    TEST(-1, 0U);
    TEST(-1, UINT_MAX);

  } catch (fail const &) {
    return TEST_EXIT_FAIL;
  } catch (std::exception const & e) {
    std::cerr << "error: " << e.what() << std::endl;
    return TEST_EXIT_ERROR;
  } catch (...) {
    return TEST_EXIT_ERROR;
  }
  return TEST_EXIT_PASS;
}
